Workbook

Sheet Export Worksheet
A1: BOOKING_DATE | B1: BANK_REFERENCE | C1: DESCRIPTION | D1: INVOICE NUMBERS | E1: VALUE_DATE | F1: DEBIT | G1: CREDIT | H1: CLOSING_BALANCE
A2: 2026-07-08 | B2: FT26189Z9S18 | C2: SZ009TRU1D9F | D2: =_xlfn.XLOOKUP(C2,SQL!D1:D126,SQL!E1:E126) -> 886189871815 | E2: 08-JUL-26 | F2: 0 | G2: 20000 | H2: 1779976
A3: 2026-07-08 | B3: FT26189J1Q2S | C3: 20144481192 | D3: 886189659968 | E3: 08-JUL-26 | F3: 0 | G3: 25000 | H3: 1804976
A4: 2026-07-08 | B4: FT26189K5ZM3 | C4: 20144483066 | D4: 886189963294 | E4: 08-JUL-26 | F4: 0 | G4: 3000 | H4: 1807976
A5: 2026-07-08 | B5: FT26189239M9 | C5: SZ609T8D5UFY | D5: =_xlfn.XLOOKUP(C5,SQL!D4:D129,SQL!E4:E129) -> 886189938482 | E5: 08-JUL-26 | F5: 0 | G5: 9000 | H5: 1816976
A6: 2026-07-08 | B6: FT26189MXT76 | C6: SZR09TYZJDEC | D6: =_xlfn.XLOOKUP(C6,SQL!D5:D130,SQL!E5:E130) -> 886189263215 | E6: 08-JUL-26 | F6: 0 | G6: 18000 | H6: 1834976
A7: 2026-07-08 | B7: FT26189MMK5J | C7: SZG09T82X77B | D7: =_xlfn.XLOOKUP(C7,SQL!D6:D131,SQL!E6:E131) -> 886189488785 | E7: 08-JUL-26 | F7: 0 | G7: 18000 | H7: 1852976
A8: 2026-07-08 | B8: FT26189SC1TX | C8: SZX09T6SZBRC | D8: =_xlfn.XLOOKUP(C8,SQL!D7:D132,SQL!E7:E132) -> 886189729391 | E8: 08-JUL-26 | F8: 0 | G8: 20000 | H8: 1872976
A9: 2026-07-08 | B9: FT26189BY8JY | C9: SZR09T6XXMWK | D9: =_xlfn.XLOOKUP(C9,SQL!D8:D133,SQL!E8:E133) -> 886189558790 | E9: 08-JUL-26 | F9: 0 | G9: 25000 | H9: 1897976
A10: 2026-07-08 | B10: FT261897DHJM | C10: SZB09TUCW3GS | D10: =_xlfn.XLOOKUP(C10,SQL!D9:D134,SQL!E9:E134) -> 886189606302 | E10: 08-JUL-26 | F10: 0 | G10: 15000 | H10: 1912976
A11: 2026-07-08 | B11: FT26189BJR7K | C11: SZR09UAYMQPC | D11: =_xlfn.XLOOKUP(C11,SQL!D10:D135,SQL!E10:E135) -> 886189501484 | E11: 08-JUL-26 | F11: 0 | G11: 3000 | H11: 1915976
A12: 2026-07-08 | B12: FT2618958LDG | C12: SZR09TQZZ560 | D12: =_xlfn.XLOOKUP(C12,SQL!D11:D136,SQL!E11:E136) -> 886189111372 | E12: 08-JUL-26 | F12: 0 | G12: 35000 | H12: 1950976
A13: 2026-07-08 | B13: FT26189Y7BX4 | C13: 20144489608 | D13: 886189023564 | E13: 08-JUL-26 | F13: 0 | G13: 48000 | H13: 1998976
A14: 2026-07-08 | B14: FT26189DMBF5 | C14: 20144481227 | D14: 886189875486 | E14: 08-JUL-26 | F14: 0 | G14: 9000 | H14: 2007976
A15: 2026-07-08 | B15: FT2618955022 | C15: SZB09T8WKD3X | D15: =_xlfn.XLOOKUP(C15,SQL!D14:D139,SQL!E14:E139) -> 886189698534 | E15: 08-JUL-26 | F15: 0 | G15: 20000 | H15: 2027976
A16: 2026-07-08 | B16: FT26189NBWKG | C16: 20144481242 | D16: 886189398153 | E16: 08-JUL-26 | F16: 0 | G16: 15000 | H16: 2042976
A17: 2026-07-08 | B17: FT261898L2B5 | C17: SZK09TQA4N5H | D17: =_xlfn.XLOOKUP(C17,SQL!D16:D141,SQL!E16:E141) -> 886189172474 | E17: 08-JUL-26 | F17: 0 | G17: 10000 | H17: 2052976
A18: 2026-07-08 | B18: FT26189RC667 | C18: 20144481245 | D18: 886189907722 | E18: 08-JUL-26 | F18: 0 | G18: 5000 | H18: 2057976
A19: 2026-07-08 | B19: FT26189VNS24 | C19: 20144485450 | D19: 886189464849 | E19: 08-JUL-26 | F19: 0 | G19: 10000 | H19: 2067976
A20: 2026-07-08 | B20: FT26189X6S37 | C20: 20144481252 | D20: 886189016234 | E20: 08-JUL-26 | F20: 0 | G20: 28000 | H20: 2095976
A21: 2026-07-08 | B21: FT26189SMNKM | C21: SZG09UFCL9G9 | D21: =_xlfn.XLOOKUP(C21,SQL!D20:D145,SQL!E20:E145) -> 886189795475 | E21: 08-JUL-26 | F21: 0 | G21: 2000 | H21: 2097976
A22: 2026-07-08 | B22: FT26189998XD | C22: 20144485529 | D22: 886189221879 | E22: 08-JUL-26 | F22: 0 | G22: 12000 | H22: 2109976
A23: 2026-07-08 | B23: FT26189ZPFFW | C23: SZ809T7SFF19 | D23: =_xlfn.XLOOKUP(C23,SQL!D22:D147,SQL!E22:E147) -> 886189900419 | E23: 08-JUL-26 | F23: 0 | G23: 5000 | H23: 2114976
A24: 2026-07-08 | B24: FT26189KG56V | C24: SZE09TRNUVBC | D24: =_xlfn.XLOOKUP(C24,SQL!D23:D148,SQL!E23:E148) -> 886189941357 | E24: 08-JUL-26 | F24: 0 | G24: 15000 | H24: 2129976
A25: 2026-07-08 | B25: FT261893Y7BT | C25: SZ009UC86YQT | D25: =_xlfn.XLOOKUP(C25,SQL!D24:D149,SQL!E24:E149) -> 886189558922 | E25: 08-JUL-26 | F25: 0 | G25: 9000 | H25: 2138976
A26: 2026-07-08 | B26: FT26189ZQ4PQ | C26: SZZ09TQMD1UC | D26: =_xlfn.XLOOKUP(C26,SQL!D25:D150,SQL!E25:E150) -> 886189297517 | E26: 08-JUL-26 | F26: 0 | G26: 4000 | H26: 2142976
A27: 2026-07-08 | B27: FT26189WBYPR | C27: 20144481256 | D27: 886189560204 | E27: 08-JUL-26 | F27: 0 | G27: 5000 | H27: 2147976
A28: 2026-07-08 | B28: FT2618925WPK | C28: SZ009TQJSYGW | D28: =_xlfn.XLOOKUP(C28,SQL!D27:D152,SQL!E27:E152) -> 886189466403 | E28: 08-JUL-26 | F28: 0 | G28: 25000 | H28: 2172976
A29: 2026-07-08 | B29: FT26189J46N0 | C29: SZM09T7J4R4T | D29: =_xlfn.XLOOKUP(C29,SQL!D28:D153,SQL!E28:E153) -> 886189830740 | E29: 08-JUL-26 | F29: 0 | G29: 20000 | H29: 2192976
A30: 2026-07-08 | B30: FT26189LSBSF | C30: SZQ09UDEZHBV | D30: =_xlfn.XLOOKUP(C30,SQL!D29:D154,SQL!E29:E154) -> 886189672277 | E30: 08-JUL-26 | F30: 0 | G30: 15000 | H30: 2207976
A31: 2026-07-08 | B31: FT261890QBG1 | C31: SZU09T04H2V3 | D31: =_xlfn.XLOOKUP(C31,SQL!D30:D155,SQL!E30:E155) -> 886189843804 | E31: 08-JUL-26 | F31: 0 | G31: 15000 | H31: 2222976
A32: 2026-07-08 | B32: FT26189S2H37 | C32: SZ809T9F6109 | D32: =_xlfn.XLOOKUP(C32,SQL!D31:D156,SQL!E31:E156) -> 886189382005 | E32: 08-JUL-26 | F32: 0 | G32: 18000 | H32: 2240976
A33: 2026-07-08 | B33: FT2618907HG5 | C33: SZ409TQR7SRA | D33: =_xlfn.XLOOKUP(C33,SQL!D32:D157,SQL!E32:E157) -> 886189797084 | E33: 08-JUL-26 | F33: 0 | G33: 30000 | H33: 2270976
A34: 2026-07-08 | B34: FT26189DKTB1 | C34: SZF09TQS3ALX | D34: =_xlfn.XLOOKUP(C34,SQL!D33:D158,SQL!E33:E158) -> 886189097864 | E34: 08-JUL-26 | F34: 0 | G34: 50000 | H34: 2320976
A35: 2026-07-08 | B35: FT26189Q9853 | C35: SZ109TZXQWCZ | D35: =_xlfn.XLOOKUP(C35,SQL!D34:D159,SQL!E34:E159) -> 886189246594 | E35: 08-JUL-26 | F35: 0 | G35: 500 | H35: 2321476
A36: 2026-07-08 | B36: FT26189K5VX5 | C36: SZW09T9LLMNY | D36: =_xlfn.XLOOKUP(C36,SQL!D35:D160,SQL!E35:E160) -> 886189703968 | E36: 08-JUL-26 | F36: 0 | G36: 3000 | H36: 2324476
A37: 2026-07-08 | B37: FT26189B5K5P | C37: SZR09UC13WPP | D37: =_xlfn.XLOOKUP(C37,SQL!D36:D161,SQL!E36:E161) -> 886189789764 | E37: 08-JUL-26 | F37: 0 | G37: 9000 | H37: 2333476
A38: 2026-07-08 | B38: FT26189FF9X6 | C38: SZB09T8LVNRV | D38: =_xlfn.XLOOKUP(C38,SQL!D37:D162,SQL!E37:E162) -> 886189147664 | E38: 08-JUL-26 | F38: 0 | G38: 6000 | H38: 2339476
A39: 2026-07-08 | B39: FT26189TVGNG | C39: SZ309TQL90KR | D39: =_xlfn.XLOOKUP(C39,SQL!D38:D163,SQL!E38:E163) -> 886189608684 | E39: 08-JUL-26 | F39: 0 | G39: 6000 | H39: 2345476
A40: 2026-07-08 | B40: FT26189BVL0S | C40: SZ209TQ6W833 | D40: 886188931458 | E40: 08-JUL-26 | F40: 0 | G40: 150000 | H40: 2495476
...

Sheet SQL
D1: 20144471688 | E1: 886188279841
D2: 20144481192 | E2: 886189659968
D3: 20144481210 | E3: 886189434771
D4: 20144481227 | E4: 886189875486
D5: 20144481228 | E5: 886189367476
D6: 20144481232 | E6: 886189807097
D7: 20144481241 | E7: 886189190660
D8: 20144481242 | E8: 886189398153
D9: 20144481245 | E9: 886189907722
D10: 20144481251 | E10: 886189137190
D11: 20144481252 | E11: 886189016234
D12: 20144481254 | E12: 886189201268
... D28: 20144489687 | E28: 886189400355
D29: SZ009T8Q9ZU1 | E29: 886189261368
D30: SZ009TQJSYGW | E30: 886189466403
D31: SZ009TRU1D9F | E31: 886189871815
D32: SZ009TT9PXEN | E32: 886189275172
D33: SZ009UC86YQT | E33: 886189558922
D34: SZ109TZXQWCZ | E34: 886189246594
D35: SZ109UBMPLB8 | E35: 886189357610
D36: SZ109UCVV2ZG | E36: 886189369954
D37: SZ209TQ6W833 | E37: 886188931458
D38: SZ309TQFKNDN | E38: 886189128656
D39: SZ309TQL90KR | E39: 886189608684
D40: SZ309TRF04R6 | E40: 886189561594
... D126: SZZ09TR6JJ1N | E126: 886189326874
