Workbook

Sheet Export Worksheet
A1: BOOKING_DATE | B1: BANK_REFERENCE | C1: DESCRIPTION | D1: INVOICE | E1: VALUE_DATE | F1: DEBIT | G1: CREDIT | H1: CLOSING_BALANCE
A2: 2026-07-22 | B2: FT26203X83VX | C2: SZS00LM9ABD0 | D2: =VLOOKUP(C2,SQL!C2:D99,2,FALSE) -> 886203135821 | E2: 22-JUL-26 | F2: 0 | G2: 500 | H2: 537500
A3: 2026-07-22 | B3: FT26203M8W1J | C3: SZ400LR0VQJY | D3: =VLOOKUP(C3,SQL!C3:D100,2,FALSE) -> 886203681601 | E3: 22-JUL-26 | F3: 0 | G3: 18000 | H3: 555500
A4: 2026-07-22 | B4: FT2620360GXW | C4: SZE00LS5XMAX | D4: =VLOOKUP(C4,SQL!C4:D101,2,FALSE) -> 886203649777 | E4: 22-JUL-26 | F4: 0 | G4: 10000 | H4: 565500
A5: 2026-07-22 | B5: FT26203Q85CX | C5: SZ700LL3Q1KC | D5: =VLOOKUP(C5,SQL!C5:D102,2,FALSE) -> 886203958617 | E5: 22-JUL-26 | F5: 0 | G5: 20000 | H5: 50500
A6: 2026-07-22 | B6: FT2620309DLZ | C6: 20144649841 | D6: 886203343724 | E6: 22-JUL-26 | F6: 0 | G6: 10000 | H6: 60500
A7: 2026-07-22 | B7: FT262031K77D | C7: SZL00LSES847 | D7: =VLOOKUP(C7,SQL!C7:D104,2,FALSE) -> 886203291562 | E7: 22-JUL-26 | F7: 0 | G7: 24000 | H7: 84500
A8: 2026-07-22 | B8: FT262032TD10 | C8: SZW00LGPX9WU | D8: =VLOOKUP(C8,SQL!C8:D105,2,FALSE) -> 886203694311 | E8: 22-JUL-26 | F8: 0 | G8: 15000 | H8: 99500
A9: 2026-07-22 | B9: FT26203Z9J7J | C9: SZR00LHC6U89 | D9: =VLOOKUP(C9,SQL!C9:D106,2,FALSE) -> 886203511487 | E9: 22-JUL-26 | F9: 0 | G9: 500 | H9: 100000
A10: 2026-07-22 | B10: FT26203GK1ZH | C10: SZR00LNCLLW3 | D10: =VLOOKUP(C10,SQL!C10:D107,2,FALSE) -> 886203511786 | E10: 22-JUL-26 | F10: 0 | G10: 3000 | H10: 103000
A11: 2026-07-22 | B11: FT26203Z3HQF | C11: SZQ00LYZU7F6 | D11: =VLOOKUP(C11,SQL!C11:D108,2,FALSE) -> 886203900186 | E11: 22-JUL-26 | F11: 0 | G11: 50000 | H11: 153000
A12: 2026-07-22 | B12: FT26203M4W09 | C12: SZ100LAVE88X | D12: =VLOOKUP(C12,SQL!C12:D109,2,FALSE) -> 886203295094 | E12: 22-JUL-26 | F12: 0 | G12: 5000 | H12: 158000
A13: 2026-07-22 | B13: FT26203LH1DK | C13: SZL00LMNK9SJ | D13: =VLOOKUP(C13,SQL!C13:D110,2,FALSE) -> 886203954518 | E13: 22-JUL-26 | F13: 0 | G13: 500 | H13: 158500
A14: 2026-07-22 | B14: FT26203Y9CCF | C14: SZM00LJRCLE1 | D14: =VLOOKUP(C14,SQL!C14:D111,2,FALSE) -> 886203273252 | E14: 22-JUL-26 | F14: 0 | G14: 500 | H14: 159000
A15: 2026-07-22 | B15: FT262039H3ZT | C15: SZS00LT8QU7Z | D15: =VLOOKUP(C15,SQL!C15:D112,2,FALSE) -> 886203673200 | E15: 22-JUL-26 | F15: 0 | G15: 500 | H15: 159500
A16: 2026-07-22 | B16: FT26203C1Q4N | C16: SZ900LLHBCV8 | D16: =VLOOKUP(C16,SQL!C16:D113,2,FALSE) -> 886203984153 | E16: 22-JUL-26 | F16: 0 | G16: 500 | H16: 160000
A17: 2026-07-22 | B17: FT262039PC72 | D17: 886051822939 | E17: 22-JUL-26 | F17: 0 | G17: 8820900 | H17: 8980900
A18: 2026-07-22 | B18: FT26203MSNNR | C18: SZD00LN2P4UC | D18: =VLOOKUP(C18,SQL!C18:D115,2,FALSE) -> 886203704871 | E18: 22-JUL-26 | F18: 0 | G18: 500 | H18: 8981400
A19: 2026-07-22 | B19: FT262030LZWX | C19: SZP00LJX0L4B | D19: =VLOOKUP(C19,SQL!C19:D116,2,FALSE) -> 886203631950 | E19: 22-JUL-26 | F19: 0 | G19: 500 | H19: 8981900
A20: 2026-07-22 | B20: FT26203MN8MP | C20: SZ800LN7UJM8 | D20: =VLOOKUP(C20,SQL!C20:D117,2,FALSE) -> 886203703862 | E20: 22-JUL-26 | F20: 0 | G20: 500 | H20: 8982400
A21: 2026-07-22 | B21: FT26203VXV6C | C21: SZV00LLNDGGR | D21: =VLOOKUP(C21,SQL!C21:D118,2,FALSE) -> 886203503239 | E21: 22-JUL-26 | F21: 0 | G21: 500 | H21: 8982900
A22: 2026-07-22 | B22: FT26203CVPK7 | C22: SZJ00LVD33GH | D22: =VLOOKUP(C22,SQL!C22:D119,2,FALSE) -> 886203386307 | E22: 22-JUL-26 | F22: 0 | G22: 20000 | H22: 9002900
A23: 2026-07-22 | B23: FT26203MMJDJ | C23: SZC00L43GNDH | D23: =VLOOKUP(C23,SQL!C23:D120,2,FALSE) -> 886203888565 | E23: 22-JUL-26 | F23: 0 | G23: 10000 | H23: 9012900
A24: 2026-07-22 | B24: FT26203Z0P3M | D24: 886049928121 | E24: 22-JUL-26 | F24: 0 | G24: 2205220 | H24: 11218120
A25: 2026-07-22 | B25: FT262032P6PP | C25: SZ500LUE9ZDC | D25: 886203888388 | E25: 22-JUL-26 | F25: 0 | G25: 500 | H25: 11218620
A26: 2026-07-22 | B26: FT26203TK4VC | C26: 20144648712 | D26: 886203689644 | E26: 22-JUL-26 | F26: 0 | G26: 10000 | H26: 11228620
A27: 2026-07-22 | B27: FT262030NXNZ | C27: 20144650027 | D27: 886203812051 | E27: 22-JUL-26 | F27: 0 | G27: 12000 | H27: 11240620
A28: 2026-07-22 | B28: FT26203HQTQR | C28: SZX00LL0751E | D28: =VLOOKUP(C28,SQL!C28:D125,2,FALSE) -> 886203046576 | E28: 22-JUL-26 | F28: 0 | G28: 500 | H28: 11241120
A29: 2026-07-22 | B29: FT26203Z13MN | C29: SZ100LUH3DS8 | D29: 886203469316 | E29: 22-JUL-26 | F29: 0 | G29: 500 | H29: 11241620
A30: 2026-07-22 | B30: FT26203LKQDL | C30: SZD00LG1TKBS | D30: =VLOOKUP(C30,SQL!C30:D127,2,FALSE) -> 886203360693 | E30: 22-JUL-26 | F30: 0 | G30: 500 | H30: 11242120
A31: 2026-07-22 | B31: FT26203HX06Q | C31: SZN00LHWQXZ5 | D31: =VLOOKUP(C31,SQL!C31:D128,2,FALSE) -> 886203148656 | E31: 22-JUL-26 | F31: 0 | G31: 500 | H31: 11242620
A32: 2026-07-22 | B32: FT26203CJH67 | C32: SZW00LSSG22B | D32: =VLOOKUP(C32,SQL!C32:D129,2,FALSE) -> 886203288290 | E32: 22-JUL-26 | F32: 0 | G32: 15000 | H32: 11257620
A33: 2026-07-22 | B33: FT26203QNYPP | C33: 20144640172 | D33: 886203178933 | E33: 22-JUL-26 | F33: 0 | G33: 12000 | H33: 11269620
A34: 2026-07-22 | B34: FT26203RF70C | C34: SZV00LTSR1Z5 | D34: =VLOOKUP(C34,SQL!C34:D131,2,FALSE) -> 886203422542 | E34: 22-JUL-26 | F34: 0 | G34: 24000 | H34: 11293620
A35: 2026-07-22 | B35: FT26203X2BZY | C35: SZG00LLDAAZ2 | D35: =VLOOKUP(C35,SQL!C35:D132,2,FALSE) -> 886203803396 | E35: 22-JUL-26 | F35: 0 | G35: 20000 | H35: 11313620
A36: 2026-07-22 | B36: FT26203TJ49S | C36: SZH00L3M9A4Q | D36: =VLOOKUP(C36,SQL!C36:D133,2,FALSE) -> 886203817758 | E36: 22-JUL-26 | F36: 0 | G36: 10000 | H36: 11323620
A37: 2026-07-22 | B37: FT262034MCZ5 | C37: SZ800L1QHTZK | D37: 886203731649 | E37: 22-JUL-26 | F37: 0 | G37: 9000 | H37: 11332620
A38: 2026-07-22 | B38: FT26203S2KD4 | C38: SZ900LSZ6C3P | D38: 886203631339 | E38: 22-JUL-26 | F38: 0 | G38: 10000 | H38: 11342620
A39: 2026-07-22 | B39: FT26203GSQKD | C39: SZD00LFQWB2Q | D39: =VLOOKUP(C39,SQL!C39:D136,2,FALSE) -> 886203113199 | E39: 22-JUL-26 | F39: 0 | G39: 12000 | H39: 11354620
A40: 2026-07-22 | B40: FT26203P1J93 | C40: SZJ00LL6CKF9 | D40: =VLOOKUP(C40,SQL!C40:D137,2,FALSE) -> 886203969689 | E40: 22-JUL-26 | F40: 0 | G40: 500 | H40: 11355120
...

Sheet SQL
C2: 20144640086 | D2: 886203609120
C3: 20144640172 | D3: 886203178933
C4: 20144640975 | D4: 886203802456
C5: 20144640999 | D5: 886203997095
C6: 20144641068 | D6: 886203215338
C7: 20144643359 | D7: 886203876634
C8: 20144644045 | D8: 886203965800
C9: 20144648712 | D9: 886203689644
C10: 20144649615 | D10: 886203278414
C11: 20144649841 | D11: 886203343724
C12: 20144650027 | D12: 886203812051
C13: SZ000L8UQFZ6 | D13: 886203945175
C14: SZ100LAVE88X | D14: 886203295094
C15: SZ100LUH3DS8 | D15: 886203469316
C16: SZ200LEAQ9AL | D16: 886203539955
C17: SZ300L1FANUX | D17: 886203312097
C18: SZ300LK5614L | D18: 886203596701
C19: SZ300LMNVPVF | D19: 886203482653
C20: SZ300LPEAE5S | D20: 886203484381
C21: SZ400LR0VQJY | D21: 886203681601
C22: SZ400LU3M25B | D22: 886203625893
C23: SZ500LCK3KRV | D23: 886203607169
C24: SZ500LUE9ZDC | D24: 886203888388
... C99: FT26203Z0P3M | D99: 886051822939
