Workbook

Sheet Export Worksheet
A1: BOOKING_DATE | B1: BANK_REFERENCE | C1: DESCRIPTION | D1: INVOICES | E1: VALUE_DATE | F1: DEBIT | G1: CREDIT | H1: CLOSING_BALANCE
A2: 2026-07-16 | B2: FT26197XT49V | C2: SZV090LS5X2D | D2: =VLOOKUP(C2,SQL!$C$2:$D$212,2,FALSE) -> 886196862578 | E2: 16-JUL-26 | F2: 0 | G2: 1200 | H2: 457900
A3: 2026-07-16 | B3: FT26197NT1DW | C3: SZG099WBAMQ0 | D3: =VLOOKUP(C3,SQL!$C$2:$D$212,2,FALSE) -> 886197375812 | E3: 16-JUL-26 | F3: 0 | G3: 8000 | H3: 465900
A4: 2026-07-16 | B4: FT26197V3CNL | C4: 20144570294 | D4: 886197386547 | E4: 16-JUL-26 | F4: 0 | G4: 5000 | H4: 470900
A5: 2026-07-16 | B5: FT26197J211W | C5: SZU099821ER2 | D5: =VLOOKUP(C5,SQL!$C$2:$D$212,2,FALSE) -> 886197574578 | E5: 16-JUL-26 | F5: 0 | G5: 500 | H5: 471400
A6: 2026-07-16 | B6: FT26197PGWT7 | C6: SZL09994UGHU | D6: =VLOOKUP(C6,SQL!$C$2:$D$212,2,FALSE) -> 886197812062 | E6: 16-JUL-26 | F6: 0 | G6: 8000 | H6: 479400
A7: 2026-07-16 | B7: FT2619759KHK | C7: SZU090L1XRMC | D7: =VLOOKUP(C7,SQL!$C$2:$D$212,2,FALSE) -> 886196095429 | E7: 16-JUL-26 | F7: 0 | G7: 500 | H7: 479900
A8: 2026-07-16 | B8: FT26197J4WG6 | C8: SZ5090TPP0YE | D8: =VLOOKUP(C8,SQL!$C$2:$D$212,2,FALSE) -> 886197331524 | E8: 16-JUL-26 | F8: 0 | G8: 10000 | H8: 489900
A9: 2026-07-16 | B9: FT261973TYJH | C9: SZ3090BF70Z5 | D9: =VLOOKUP(C9,SQL!$C$2:$D$212,2,FALSE) -> 886197825934 | E9: 16-JUL-26 | F9: 0 | G9: 72000 | H9: 561900
A10: 2026-07-16 | B10: FT26197XGTQZ | C10: SZ0090D61VC7 | D10: =VLOOKUP(C10,SQL!$C$2:$D$212,2,FALSE) -> 886197083682 | E10: 16-JUL-26 | F10: 0 | G10: 20000 | H10: 581900
A11: 2026-07-16 | B11: FT26197BZC2L | C11: SZL0990AGGXA | D11: =VLOOKUP(C11,SQL!$C$2:$D$212,2,FALSE) -> 886197218096 | E11: 16-JUL-26 | F11: 0 | G11: 5000 | H11: 586900
A12: 2026-07-16 | B12: FT26197FL3WN | C12: SZN0997U8TVP | D12: =VLOOKUP(C12,SQL!$C$2:$D$212,2,FALSE) -> 886197960093 | E12: 16-JUL-26 | F12: 0 | G12: 19000 | H12: 605900
A13: 2026-07-16 | B13: FT261970YMH9 | C13: SZ4090LQQCPB | D13: =VLOOKUP(C13,SQL!$C$2:$D$212,2,FALSE) -> 886196170765 | E13: 16-JUL-26 | F13: 0 | G13: 1200 | H13: 607100
A14: 2026-07-16 | B14: FT26197S25S6 | C14: SZD090LYJ5Z4 | D14: =VLOOKUP(C14,SQL!$C$2:$D$212,2,FALSE) -> 886196072127 | E14: 16-JUL-26 | F14: 0 | G14: 500 | H14: 607600
A15: 2026-07-16 | B15: FT26197F74ZB | C15: SZD090QV9T2D | D15: =VLOOKUP(C15,SQL!$C$2:$D$212,2,FALSE) -> 886197377241 | E15: 16-JUL-26 | F15: 0 | G15: 8000 | H15: 615600
A16: 2026-07-16 | B16: FT2619752KLB | C16: SZ5090L4NJT2 | D16: =VLOOKUP(C16,SQL!$C$2:$D$212,2,FALSE) -> 886197710587 | E16: 16-JUL-26 | F16: 0 | G16: 1200 | H16: 616800
... A30: 2026-07-16 | B30: FT261971LD00 | C30: SZB0991RA8UB | D30: =VLOOKUP(C30,SQL!$C$2:$D$212,2,FALSE) -> 886197916772 | E30: 16-JUL-26 | F30: 0 | G30: 5000 | H30: 565678
A31: 2026-07-16 | B31: FT26197W57QF | C31: 20144570972 | D31: 886196873806 | E31: 16-JUL-26 | F31: 0 | G31: 150000 | H31: 715678
A32: 2026-07-16 | B32: FT26197NLKNX | C32: SZK0999YRXC3 | D32: =VLOOKUP(C32,SQL!$C$2:$D$212,2,FALSE) -> 886197892751 | E32: 16-JUL-26 | F32: 0 | G32: 12000 | H32: 727678
A33: 2026-07-16 | B33: FT2619767J60 | C33: SZ3099YXKSGF | D33: =VLOOKUP(C33,SQL!$C$2:$D$212,2,FALSE) -> 886197295501 | E33: 16-JUL-26 | F33: 0 | G33: 30000 | H33: 757678
A34: 2026-07-16 | B34: FT26197XFPGR | C34: SZU090DQG432 | D34: =VLOOKUP(C34,SQL!$C$2:$D$212,2,FALSE) -> 886197470431 | E34: 16-JUL-26 | F34: 0 | G34: 500 | H34: 758178
A35: 2026-07-16 | B35: FT26197FBHY0 | C35: SZR090LFC2XQ | D35: =VLOOKUP(C35,SQL!$C$2:$D$212,2,FALSE) -> 886197052296 | E35: 16-JUL-26 | F35: 0 | G35: 35000 | H35: 793178
A36: 2026-07-16 | B36: FT26197F223B | C36: SZ50994JYVEF | D36: =VLOOKUP(C36,SQL!$C$2:$D$212,2,FALSE) -> 886197011133 | E36: 16-JUL-26 | F36: 0 | G36: 15000 | H36: 808178
A37: 2026-07-16 | B37: FT2619757BH6 | C37: SZU090C5ELJ6 | D37: =VLOOKUP(C37,SQL!$C$2:$D$212,2,FALSE) -> 886197919675 | E37: 16-JUL-26 | F37: 0 | G37: 16000 | H37: 824178
A38: 2026-07-17 | B38: FT26198T6QDJ | C38: SZ800A812K43 | D38: =VLOOKUP(C38,SQL!$C$2:$D$212,2,FALSE) -> 886198966420 | E38: 17-JUL-26 | F38: 0 | G38: 24000 | H38: 848178
A39: 2026-07-17 | B39: FT261988WDSF | C39: SZR00BQ4S0R7 | D39: =VLOOKUP(C39,SQL!$C$2:$D$212,2,FALSE) -> 886198658092 | E39: 17-JUL-26 | F39: 0 | G39: 5000 | H39: 853178
A40: 2026-07-17 | B40: FT26198FHY3M | C40: SZB00A48CD53 | D40: =VLOOKUP(C40,SQL!$C$2:$D$212,2,FALSE) -> 886198855361 | E40: 17-JUL-26 | F40: 0 | G40: 16000 | H40: 869178
A41: 2026-07-17 | B41: FT26198B2Q0J | C41: SZU00BR5BVFK | D41: =VLOOKUP(C41,SQL!$C$2:$D$212,2,FALSE) -> 886198117681 | E41: 17-JUL-26 | F41: 0 | G41: 5000 | H41: 874178
A42: 2026-07-17 | B42: FT261983NR3J | C42: SZZ00BB5NU0E | D42: =VLOOKUP(C42,SQL!$C$2:$D$212,2,FALSE) -> 876198106005 | E42: 17-JUL-26 | F42: 0 | G42: 10000 | H42: 884178
A43: 2026-07-17 | B43: FT26198PJ8JH | C43: SZH00A6MWBNF | D43: =VLOOKUP(C43,SQL!$C$2:$D$212,2,FALSE) -> 886198192915 | E43: 17-JUL-26 | F43: 0 | G43: 25000 | H43: 909178
... A94: 2026-07-17 | B94: FT26198LTQ9F | C94: SZQ00A7JSSZY | D94: =VLOOKUP(C94,SQL!$C$2:$D$212,2,FALSE) -> 886198754914 | E94: 17-JUL-26 | F94: 0 | G94: 500 | H94: 894500
A95: 2026-07-17 | B95: FT26198FKM1D | C95: 20144583158 | D95: 876198074691 | E95: 17-JUL-26 | F95: 0 | G95: 172500 | H95: 1067000
A96: 2026-07-17 | B96: FT26198CH3T6 | C96: SZK00A7NZ8YA | D96: =VLOOKUP(C96,SQL!$C$2:$D$212,2,FALSE) -> 886198776988 | E96: 17-JUL-26 | F96: 0 | G96: 25000 | H96: 1092000
A97: 2026-07-17 | B97: FT26198YKBB8 | C97: SZZ00AUE3ERR | D97: =VLOOKUP(C97,SQL!$C$2:$D$212,2,FALSE) -> 886198021172 | E97: 17-JUL-26 | F97: 0 | G97: 500 | H97: 1092500
A98: 2026-07-17 | B98: FT26198YGDNF | C98: SZG00BD44B0A | D98: =VLOOKUP(C98,SQL!$C$2:$D$212,2,FALSE) -> 886198340960 | E98: 17-JUL-26 | F98: 0 | G98: 500 | H98: 1093000
A99: 2026-07-17 | B99: FT261988NMBK | C99: SZM00BEX702S | D99: =VLOOKUP(C99,SQL!$C$2:$D$212,2,FALSE) -> 886198176675 | E99: 17-JUL-26 | F99: 0 | G99: 15000 | H99: 1108000
A100: 2026-07-17 | B100: FT26198GSXZK | C100: SZ400AQF4KTS | D100: =VLOOKUP(C100,SQL!$C$2:$D$212,2,FALSE) -> 886198669110 | E100: 17-JUL-26 | F100: 0 | G100: 8000 | H100: 1116000
A101: 2026-07-17 | B101: FT261988FTD5 | C101: SZP00A8JGAC8 | D101: =VLOOKUP(C101,SQL!$C$2:$D$212,2,FALSE) -> 886198972976 | E101: 17-JUL-26 | F101: 0 | G101: 35000 | H101: 1151000
A102: 2026-07-17 | B102: FT26198JD6WL | C102: SZ800A5BLWBC | D102: =VLOOKUP(C102,SQL!$C$2:$D$212,2,FALSE) -> 886198599803 | E102: 17-JUL-26 | F102: 0 | G102: 20000 | H102: 1171000
A103: 2026-07-17 | B103: FT26198DVQ2J | C103: SZ400BFZHAUG | D103: =VLOOKUP(C103,SQL!$C$2:$D$212,2,FALSE) -> 886198061507 | E103: 17-JUL-26 | F103: 0 | G103: 20000 | H103: 1191000
...

Sheet SQL
C2: 20144570294 | D2: 886197386547
C3: 20144570972 | D3: 886196873806
C4: 20144583158 | D4: 876198074691
C5: 20144594783 | D5: 886198977332
C6: 20144601501 | D6: 886199712600
C7: 20144603156 | D7: 886199397597
C8: 20144605112 | D8: 886199533161
C9: SZ000AP3FEEM | D9: 886198170061
C10: SZ000BAS6MDZ | D10: 886198998765
C11: SZ000FJCK667 | D11: 886200650618
C12: SZ0090D61VC7 | D12: 886197083682
C13: SZ100A4WJKCW | D13: 886198637074
C14: SZ100A5VNK5A | D14: 886198038037
C15: SZ200A6V98DA | D15: 886198087315
C16: SZ200E40MKV4 | D16: 886200290819
C17: SZ200E448CDA | D17: 886200477479
C18: SZ200E6CK0XZ | D18: 886200142834
C19: SZ200FDAJCNK | D19: 886200271747
C20: SZ200FENY8KX | D20: 886200545774
... C127: SZL00BHKHUXC | D127: 886198186339
C128: SZL00C655PW8 | D128: payment","in
C129: SZL00E3P3FAH | D129: 886200992359
C130: SZL00E5ZL4SG | D130: 886200178245
C131: SZL00FEJDCVR | D131: 886200635420
C132: SZL00FERR1UY | D132: 886200768063
C133: SZL0990AGGXA | D133: 886197218096
C134: SZL09994UGHU | D134: 886197812062
C135: SZL099VY4DK3 | D135: 886197706720
C136: SZM00A5XWCWG | D136: 886198249073
C137: SZM00BEX702S | D137: 886198176675
C138: SZM00CVLZQR0 | D138: 886199695337
C139: SZM00E3JD5D9 | D139: 886200216215
C140: SZM00E41YT6F | D140: 886200458394
... C212: SZZ00FA831VM | D212: 886200604535
