Workbook

Sheet Export Worksheet
A1: BOOKING_DATE | B1: BANK_REFERENCE | C1: DESCRIPTION | D1: INVOICE | E1: VALUE_DATE | F1: DEBIT | G1: CREDIT | H1: CLOSING_BALANCE
A2: 2026-07-20 | B2: FT26201PPMTF | C2: SZA00GSPVG50 | D2: =VLOOKUP(C2,SQL!$D$2:$E$65,2,FALSE) -> 886201071824 | E2: 20-JUL-26 | F2: 0 | G2: 13000 | H2: 488008
A3: 2026-07-20 | B3: FT262013WWQ4 | C3: SZA00GG5KP8X | D3: =VLOOKUP(C3,SQL!$D$2:$E$65,2,FALSE) -> 886201548722 | E3: 20-JUL-26 | F3: 0 | G3: 5000 | H3: 200508
A4: 2026-07-20 | B4: FT26201KDC2Y | C4: SZ500G1QY0WV | D4: =VLOOKUP(C4,SQL!$D$2:$E$65,2,FALSE) -> 886201697374 | E4: 20-JUL-26 | F4: 0 | G4: 1200 | H4: 201708
A5: 2026-07-20 | B5: FT26201BSKYR | C5: SZM00GQR64EK | D5: =VLOOKUP(C5,SQL!$D$2:$E$65,2,FALSE) -> 886201538085 | E5: 20-JUL-26 | F5: 0 | G5: 10000 | H5: 211708
A6: 2026-07-20 | B6: FT26201VD1X3 | C6: SZN00G2J208N | D6: =VLOOKUP(C6,SQL!$D$2:$E$65,2,FALSE) -> 886201135631 | E6: 20-JUL-26 | F6: 0 | G6: 21000 | H6: 232708
A7: 2026-07-20 | B7: FT26201YKKW9 | C7: SZD00GVURNCX | D7: =VLOOKUP(C7,SQL!$D$2:$E$65,2,FALSE) -> 886201257709 | E7: 20-JUL-26 | F7: 0 | G7: 24000 | H7: 256708
A8: 2026-07-20 | B8: FT26201N634B | C8: SZV00GWTEM4Q | D8: =VLOOKUP(C8,SQL!$D$2:$E$65,2,FALSE) -> 886201369020 | E8: 20-JUL-26 | F8: 0 | G8: 10000 | H8: 266708
A9: 2026-07-20 | B9: FT26201PQ6Y4 | C9: SZT00GNNXXPP | D9: =VLOOKUP(C9,SQL!$D$2:$E$65,2,FALSE) -> 886201245670 | E9: 20-JUL-26 | F9: 0 | G9: 500 | H9: 267208
A10: 2026-07-20 | B10: FT26201LS1DV | C10: SZ900GNTE0EH | D10: =VLOOKUP(C10,SQL!$D$2:$E$65,2,FALSE) -> 886201548073 | E10: 20-JUL-26 | F10: 0 | G10: 500 | H10: 267708
A11: 2026-07-20 | B11: FT26201Q5TSQ | C11: SZ100GYEG7B5 | D11: =VLOOKUP(C11,SQL!$D$2:$E$65,2,FALSE) -> 886201387577 | E11: 20-JUL-26 | F11: 0 | G11: 12000 | H11: 279708
A12: 2026-07-20 | B12: FT26201D156B | C12: SZ400G9FESTX | D12: =VLOOKUP(C12,SQL!$D$2:$E$65,2,FALSE) -> 886201057266 | E12: 20-JUL-26 | F12: 0 | G12: 1000 | H12: 280708
A13: 2026-07-20 | B13: FT26201GSK6V | C13: SZN00GWPBPCW | D13: =VLOOKUP(C13,SQL!$D$2:$E$65,2,FALSE) -> 886201329082 | E13: 20-JUL-26 | F13: 0 | G13: 5000 | H13: 285708
... A26: 2026-07-20 | B26: FT262011FH0M | C26: SZS00GTUP5HA | D26: =VLOOKUP(C26,SQL!$D$2:$E$65,2,FALSE) -> 886201623410 | E26: 20-JUL-26 | F26: 0 | G26: 20000 | H26: 440408
A27: 2026-07-20 | B27: FT26201KXLLQ | C27: 20144624938 | D27: 876201493184 | E27: 20-JUL-26 | F27: 0 | G27: 210000 | H27: 650408
A28: 2026-07-20 | B28: FT26201X2LD5 | C28: SZ000G4NSTW1 | D28: =VLOOKUP(C28,SQL!$D$2:$E$65,2,FALSE) -> 886201598082 | E28: 20-JUL-26 | F28: 0 | G28: 1200 | H28: 651608
A29: 2026-07-20 | B29: FT262015J7N4 | C29: SZT00GFWRXEY | D29: =VLOOKUP(C29,SQL!$D$2:$E$65,2,FALSE) -> 886201121935 | E29: 20-JUL-26 | F29: 0 | G29: 15000 | H29: 666608
A30: 2026-07-20 | B30: FT2620199NNH | C30: SZK00GNVD35B | D30: =VLOOKUP(C30,SQL!$D$2:$E$65,2,FALSE) -> 886201270884 | E30: 20-JUL-26 | F30: 0 | G30: 8000 | H30: 674608
A31: 2026-07-20 | B31: FT262015C85K | C31: SZ400GF7CT9S | D31: =VLOOKUP(C31,SQL!$D$2:$E$65,2,FALSE) -> 886201620258 | E31: 20-JUL-26 | F31: 0 | G31: 500 | H31: 675108
A32: 2026-07-20 | B32: FT26201KMH4X | C32: SZU00GGDMZ7N | D32: =VLOOKUP(C32,SQL!$D$2:$E$65,2,FALSE) -> 886201920868 | E32: 20-JUL-26 | F32: 0 | G32: 1500 | H32: 676608
A33: 2026-07-20 | B33: FT2620137FX3 | C33: SZA00G837HQK | D33: =VLOOKUP(C33,SQL!$D$2:$E$65,2,FALSE) -> 886201007924 | E33: 20-JUL-26 | F33: 0 | G33: 500 | H33: 677108
A34: 2026-07-20 | B34: FT26201T849Y | C34: SZN00GTJ4WY4 | D34: =VLOOKUP(C34,SQL!$D$2:$E$65,2,FALSE) -> 886201623410 | E34: 20-JUL-26 | F34: 0 | G34: 20000 | H34: 697108
A35: 2026-07-20 | B35: FT26201N850Z | C35: SZB00GZF3BG5 | D35: =VLOOKUP(C35,SQL!$D$2:$E$65,2,FALSE) -> 886201849485 | E35: 20-JUL-26 | F35: 0 | G35: 3000 | H35: 700108
A36: 2026-07-20 | B36: FT26201TXV5P | C36: SZM00GR23D3D | D36: =VLOOKUP(C36,SQL!$D$2:$E$65,2,FALSE) -> 886201835909 | E36: 20-JUL-26 | F36: 0 | G36: 500 | H36: 700608
A37: 2026-07-20 | B37: FT26201FCB55 | C37: SZ500G2WGQB7 | D37: =VLOOKUP(C37,SQL!$D$2:$E$65,2,FALSE) -> 886201272240 | E37: 20-JUL-26 | F37: 0 | G37: 35000 | H37: 735608
A38: 2026-07-20 | B38: FT26201VWFNL | C38: SZR00GYQW7BD | D38: =VLOOKUP(C38,SQL!$D$2:$E$65,2,FALSE) -> 886201368768 | E38: 20-JUL-26 | F38: 0 | G38: 15000 | H38: 750608
A39: 2026-07-20 | B39: FT262015X1SH | C39: SZJ00GPTRXE8 | D39: =VLOOKUP(C39,SQL!$D$2:$E$65,2,FALSE) -> 886201518962 | E39: 20-JUL-26 | F39: 0 | G39: 500 | H39: 751108
A40: 2026-07-20 | B40: FT262014FYZ6 | C40: 20144616465 | D40: 886201801279 | E40: 20-JUL-26 | F40: 0 | G40: 15000 | H40: 766108
A41: 2026-07-20 | B41: FT262011JYGD | C41: SZ600G8X9J7R | D41: =VLOOKUP(C41,SQL!$D$2:$E$65,2,FALSE) -> 886201841941 | E41: 20-JUL-26 | F41: 0 | G41: 5000 | H41: 771108
A42: 2026-07-20 | B42: FT262018TL8N | C42: SZR00GRRWHN3 | D42: =VLOOKUP(C42,SQL!$D$2:$E$65,2,FALSE) -> 886201558686 | E42: 20-JUL-26 | F42: 0 | G42: 16000 | H42: 787108
A43: 2026-07-20 | B43: FT2620183CN2 | C43: SZN00GREBEVH | D43: =VLOOKUP(C43,SQL!$D$2:$E$65,2,FALSE) -> 886201253768 | E43: 20-JUL-26 | F43: 0 | G43: 8000 | H43: 795108
A44: 2026-07-20 | B44: FT2620179XL5 | C44: SZD00GN0567A | D44: =VLOOKUP(C44,SQL!$D$2:$E$65,2,FALSE) -> 886201111040 | E44: 20-JUL-26 | F44: 0 | G44: 6000 | H44: 801108
A45: 2026-07-20 | B45: FT26201XL8D5 | C45: SZC00GGLWNH6 | D45: =VLOOKUP(C45,SQL!$D$2:$E$65,2,FALSE) -> 886201108595 | E45: 20-JUL-26 | F45: 0 | G45: 15000 | H45: 816108
A46: 2026-07-20 | B46: FT26201Y099G | C46: SZQ00GV1TF1D | D46: =VLOOKUP(C46,SQL!$D$2:$E$65,2,FALSE) -> 886201303014 | E46: 20-JUL-26 | F46: 0 | G46: 10000 | H46: 826108
A47: 2026-07-20 | B47: FT26201MK3YZ | C47: SZH00GL3ADWV | D47: =VLOOKUP(C47,SQL!$D$2:$E$65,2,FALSE) -> 886199184593 | E47: 20-JUL-26 | F47: 0 | G47: 100000 | H47: 926108
A48: 2026-07-20 | B48: FT26201CLKVJ | C48: SZJ00G2ZLMY7 | D48: =VLOOKUP(C48,SQL!$D$2:$E$65,2,FALSE) -> 886201616363 | E48: 20-JUL-26 | F48: 0 | G48: 3000 | H48: 929108
A49: 2026-07-20 | B49: FT26201CJBZW | C49: 20144616494 | D49: 886201775740 | E49: 20-JUL-26 | F49: 0 | G49: 48000 | H49: 977108
A50: 2026-07-20 | B50: FT26201141XT | C50: SZ400GREP429 | D50: =VLOOKUP(C50,SQL!$D$2:$E$65,2,FALSE) -> 886201540482 | E50: 20-JUL-26 | F50: 0 | G50: 6000 | H50: 983108
A51: 2026-07-20 | B51: FT262015W2NB | C51: SZ800G41AUHG | D51: =VLOOKUP(C51,SQL!$D$2:$E$65,2,FALSE) -> 886201094439 | E51: 20-JUL-26 | F51: 0 | G51: 35000 | H51: 1018108
A52: 2026-07-20 | B52: FT262012YVDW | C52: SZN00GH2LE46 | D52: =VLOOKUP(C52,SQL!$D$2:$E$65,2,FALSE) -> 886201735944 | E52: 20-JUL-26 | F52: 0 | G52: 20000 | H52: 1038108
...

Sheet SQL
D2: 20144616465 | E2: 886201801279
D3: 20144616494 | E3: 886201775740
D4: 20144617161 | E4: 886201422206
D5: 20144618197 | E5: 886201021412
D6: 20144624938 | E6: 876201493184
D7: SZ000G4NSTW1 | E7: 886201598082
D8: SZ100G1DY7HN | E8: 886201022373
D9: SZ100GLYLPHJ | E9: 886201500581
D10: SZ100GTWV2RU | E10: 886201527847
D11: SZ100GYEG7B5 | E11: 886201387577
D12: SZ400G9FESTX | E12: 886201057266
D13: SZ400GF7CT9S | E13: 886201620258
D14: SZ400GREP429 | E14: 886201540482
D15: SZ500G1QY0WV | E15: 886201697374
D16: SZ500G2WGQB7 | E16: 886201272240
D17: SZ600G8X9J7R | E17: 886201841941
D18: SZ600GSARAAN | E18: 886201528748
... D65: SZZ00GSTBAPR | E65: 886201842524
