Workbook

Sheet Export Worksheet
A1: BOOKING_DATE | B1: BANK_REFERENCE | C1: DESCRIPTION | D1: INVOICE NUMBER | E1: VALUE_DATE | F1: DEBIT | G1: CREDIT | H1: CLOSING_BALANCE
A2: 2026-07-13 | B2: FT26194J7Z13 | C2: SZP094VQC48M | D2: =_xlfn.XLOOKUP(C2,SQL!C2:C65,SQL!D2:D65) -> 886194985683 | E2: 13-JUL-26 | F2: 0 | G2: 500 | H2: 271000
A3: 2026-07-13 | B3: FT26194GPWV8 | C3: SZX094TY9L1V | D3: =_xlfn.XLOOKUP(C3,SQL!C3:C66,SQL!D3:D66) -> 886194667963 | E3: 13-JUL-26 | F3: 0 | G3: 500 | H3: 271500
A4: 2026-07-13 | B4: FT26194Q4Z1N | C4: SZX094CUQ3AN | D4: =_xlfn.XLOOKUP(C4,SQL!C4:C67,SQL!D4:D67) -> 886194590974 | E4: 13-JUL-26 | F4: 0 | G4: 35000 | H4: 306500
A5: 2026-07-13 | B5: FT26194KQBF6 | C5: SZ6094DD91VJ | D5: =_xlfn.XLOOKUP(C5,SQL!C5:C68,SQL!D5:D68) -> 886194284570 | E5: 13-JUL-26 | F5: 0 | G5: 5000 | H5: 311500
A6: 2026-07-13 | B6: FT26194WQ3L5 | C6: SZH094TR4HGA | D6: =_xlfn.XLOOKUP(C6,SQL!C6:C69,SQL!D6:D69) -> 886194741160 | E6: 13-JUL-26 | F6: 0 | G6: 12000 | H6: 323500
A7: 2026-07-13 | B7: FT261942BYNW | C7: SZW094U0V90P | D7: =_xlfn.XLOOKUP(C7,SQL!C7:C70,SQL!D7:D70) -> 886194872572 | E7: 13-JUL-26 | F7: 0 | G7: 5000 | H7: 328500
A8: 2026-07-13 | B8: FT26194F3L9N | C8: SZS094Q1EJ9J | D8: =_xlfn.XLOOKUP(C8,SQL!C8:C71,SQL!D8:D71) -> 886194708707 | E8: 13-JUL-26 | F8: 0 | G8: 500 | H8: 329000
A9: 2026-07-13 | B9: FT261941RPG8 | C9: SZX094XRC8N0 | D9: =_xlfn.XLOOKUP(C9,SQL!C9:C72,SQL!D9:D72) -> 886194502255 | E9: 13-JUL-26 | F9: 0 | G9: 3000 | H9: 332000
A10: 2026-07-13 | B10: FT26194J1047 | C10: SZD094NZ98Q5 | D10: =_xlfn.XLOOKUP(C10,SQL!C10:C73,SQL!D10:D73) -> 886194256600 | E10: 13-JUL-26 | F10: 0 | G10: 500 | H10: 332500
A11: 2026-07-13 | B11: FT261945MMYV | C11: SZ0094WZM5MR | D11: 886194154180 | E11: 13-JUL-26 | F11: 0 | G11: 12000 | H11: 344500
A12: 2026-07-13 | B12: FT26194TD3S3 | C12: SZU094XW2MFR | D12: =_xlfn.XLOOKUP(C12,SQL!C12:C75,SQL!D12:D75) -> 886194682426 | E12: 13-JUL-26 | F12: 0 | G12: 500 | H12: 345000
A13: 2026-07-13 | B13: FT26194L1N48 | C13: SZF094RRGR5N | D13: =_xlfn.XLOOKUP(C13,SQL!C13:C76,SQL!D13:D76) -> 886194546899 | E13: 13-JUL-26 | F13: 0 | G13: 5000 | H13: 350000
A14: 2026-07-13 | B14: FT26194BSF4B | C14: SZR094KFE4N1 | D14: =_xlfn.XLOOKUP(C14,SQL!C14:C77,SQL!D14:D77) -> 886194943311 | E14: 13-JUL-26 | F14: 0 | G14: 6000 | H14: 356000
A15: 2026-07-13 | B15: FT26194RCNLW | C15: SZT094N5RMC4 | D15: =_xlfn.XLOOKUP(C15,SQL!C15:C78,SQL!D15:D78) -> 886194969854 | E15: 13-JUL-26 | F15: 0 | G15: 500 | H15: 356500
A16: 2026-07-13 | B16: FT261942HVPL | C16: SZU0938DSDR3 | D16: =_xlfn.XLOOKUP(C16,SQL!C16:C79,SQL!D16:D79) -> 886194661438 | E16: 13-JUL-26 | F16: 0 | G16: 3000 | H16: 359500
A17: 2026-07-13 | B17: FT26194BVQGF | C17: SZC094FTGYSK | D17: =_xlfn.XLOOKUP(C17,SQL!C17:C80,SQL!D17:D80) -> 886194358960 | E17: 13-JUL-26 | F17: 0 | G17: 10000 | H17: 369500
A18: 2026-07-13 | B18: FT261945NVWQ | C18: SZB094CH526G | D18: =_xlfn.XLOOKUP(C18,SQL!C18:C81,SQL!D18:D81) -> 886194348611 | E18: 13-JUL-26 | F18: 0 | G18: 1500 | H18: 371000
A19: 2026-07-13 | B19: FT261941X89R | C19: SZY094W7RUQN | D19: =_xlfn.XLOOKUP(C19,SQL!C19:C82,SQL!D19:D82) -> 886194846083 | E19: 13-JUL-26 | F19: 0 | G19: 10000 | H19: 381000
A20: 2026-07-13 | B20: FT26194MZQVS | C20: SZK0937ULTJ9 | D20: =_xlfn.XLOOKUP(C20,SQL!C20:C83,SQL!D20:D83) -> 886194605743 | E20: 13-JUL-26 | F20: 0 | G20: 10000 | H20: 391000
A21: 2026-07-13 | B21: FT261940WM2K | C21: SZE0925YQGWA | D21: =_xlfn.XLOOKUP(C21,SQL!C21:C84,SQL!D21:D84) -> 886193673122 | E21: 12-JUL-26 | F21: 0 | G21: 100000 | H21: 491000
A22: 2026-07-13 | B22: FT26194DQNQB | C22: SZG094TXE792 | D22: =_xlfn.XLOOKUP(C22,SQL!C22:C85,SQL!D22:D85) -> 886194714005 | E22: 13-JUL-26 | F22: 0 | G22: 500 | H22: 491500
A23: 2026-07-13 | B23: FT26194FP7XN | C23: SZR094C6RDNR | D23: =_xlfn.XLOOKUP(C23,SQL!C23:C86,SQL!D23:D86) -> 886194825445 | E23: 13-JUL-26 | F23: 0 | G23: 6000 | H23: 497500
A24: 2026-07-13 | B24: FT26194X04PF | C24: SZ00928J2T7M | D24: 886193704574 | E24: 12-JUL-26 | F24: 0 | G24: 20000 | H24: 517500
A25: 2026-07-13 | B25: FT26194T1CNJ | C25: SZ70928P2Y22 | D25: 886193224353 | E25: 12-JUL-26 | F25: 0 | G25: 15000 | H25: 532500
A26: 2026-07-13 | B26: FT26194GX1FH | C26: SZZ094Z956HU | D26: =_xlfn.XLOOKUP(C26,SQL!C26:C89,SQL!D26:D89) -> 886194711376 | E26: 13-JUL-26 | F26: 0 | G26: 6000 | H26: 538500
A27: 2026-07-13 | B27: FT261949LLB4 | C27: SZL094TS4VBR | D27: =_xlfn.XLOOKUP(C27,SQL!C27:C90,SQL!D27:D90) -> 886194515819 | E27: 13-JUL-26 | F27: 0 | G27: 40000 | H27: 578500
A28: 2026-07-13 | B28: FT26194RJRKN | C28: SZY094AT23R0 | D28: =_xlfn.XLOOKUP(C28,SQL!C28:C91,SQL!D28:D91) -> 886194712318 | E28: 13-JUL-26 | F28: 0 | G28: 20000 | H28: 598500
A29: 2026-07-13 | B29: FT26194G4317 | C29: SZD094BETQLY | D29: 886194823614 | E29: 13-JUL-26 | F29: 0 | G29: 8000 | H29: 606500
A30: 2026-07-13 | B30: FT261941QJDC | C30: SZX093229FBU | D30: =_xlfn.XLOOKUP(C30,SQL!C30:C93,SQL!D30:D93) -> 886194494194 | E30: 13-JUL-26 | F30: 0 | G30: 16000 | H30: 622500
A31: 2026-07-13 | B31: FT261943068R | C31: SZ00926L5LWE | D31: 886193322764 | E31: 12-JUL-26 | F31: 0 | G31: 32000 | H31: 654500
A32: 2026-07-13 | B32: FT26194M4FVG | C32: SZV094FWN8RC | D32: =_xlfn.XLOOKUP(C32,SQL!C32:C95,SQL!D32:D95) -> 886194186876 | E32: 13-JUL-26 | F32: 0 | G32: 5000 | H32: 659500
A33: 2026-07-13 | B33: FT261948QN09 | C33: SZX094E4B0HJ | D33: =_xlfn.XLOOKUP(C33,SQL!C33:C96,SQL!D33:D96) -> 886194042979 | E33: 13-JUL-26 | F33: 0 | G33: 18000 | H33: 677500
A34: 2026-07-13 | B34: FT26194W36N5 | C34: SZK094M62NL3 | D34: =_xlfn.XLOOKUP(C34,SQL!C34:C97,SQL!D34:D97) -> 886194246158 | E34: 13-JUL-26 | F34: 0 | G34: 10000 | H34: 687500
A35: 2026-07-13 | B35: FT261941RSZV | C35: SZ40936YSVN4 | D35: 886194440905 | E35: 13-JUL-26 | F35: 0 | G35: 21000 | H35: 708500
A36: 2026-07-13 | B36: FT2619475T1R | C36: SZN0930VQQT6 | D36: =_xlfn.XLOOKUP(C36,SQL!C36:C99,SQL!D36:D99) -> 886194423899 | E36: 13-JUL-26 | F36: 0 | G36: 3000 | H36: 711500
A37: 2026-07-13 | B37: FT26194WKCH9 | C37: SZA094CNX873 | D37: 886194778708 | E37: 13-JUL-26 | F37: 0 | G37: 500 | H37: 712000
A38: 2026-07-13 | B38: FT26194XDCB3 | C38: SZB094MDVBYU | D38: 886194966584 | E38: 13-JUL-26 | F38: 0 | G38: 500 | H38: 712500
A39: 2026-07-13 | B39: FT26194YY1DW | C39: SZQ094E5LCYG | D39: =_xlfn.XLOOKUP(C39,SQL!C39:C102,SQL!D39:D102) -> 886194807832 | E39: 13-JUL-26 | F39: 0 | G39: 40000 | H39: 752500
A40: 2026-07-13 | B40: FT261945K7CN | C40: SZ3094T2HFHZ | D40: 886194893492 | E40: 13-JUL-26 | F40: 0 | G40: 15000 | H40: 767500
...

Sheet SQL
C2: SZ00926L5LWE | D2: 886193322764
C3: SZ00928J2T7M | D3: 886193704574
C4: SZ0094WZM5MR | D4: 886194154180
C5: SZ1094X2FV1S | D5: 886194700459
C6: SZ3094T2HFHZ | D6: 886194893492
C7: SZ40936YSVN4 | D7: 886194440905
C8: SZ4094WWEXA0 | D8: 886194799869
C9: SZ5094VTH8NC | D9: 886194175145
C10: SZ6094DD91VJ | D10: 886194284570
C11: SZ70928P2Y22 | D11: 886193224353
C12: SZ7094T4DSUH | D12: 886194896455
C13: SZ8094TV1A1C | D13: 886194129588
... C65: SZZ094Z956HU | D65: 886194711376
